Workbook

Sheet 안내
A1: 데이터 표준 사전
A3: 구성 | B3: 표준단어 → 표준도메인 → 표준용어 순으로 정의하고, 코드값은 표준코드 시트에서 관리한다.
A4: 명명 규칙 1 | B4: 물리명은 영문 대문자 약어를 밑줄(_)로 연결한다. 예: 주문 + 일시 = ORD_DTM
A5: 명명 규칙 2 | B5: 모든 표준용어는 분류어(ID, 번호, 코드, 명, 일시, 일자, 금액, 수량 등)로 끝나며, 분류어가 도메인을 결정한다.
A6: 명명 규칙 3 | B6: 같은 의미의 단어는 하나만 표준으로 쓰고 나머지는 금칙어로 등록한다. 예: 변동(표준) / 변경(금칙어)
A7: 명명 규칙 4 | B7: 원천 시스템의 식별자는 '원천' 단어를 붙여 대체키와 구분한다. 예: 원천주문번호 SRC_ORD_NO
A8: 명명 규칙 5 | B8: 표준 사전과 ERD는 대문자로 표기하고, MySQL에는 소문자로 생성한다. 한글 논리명은 컬럼 COMMENT로 남긴다.
A9: 대상 DBMS | B9: MySQL
A11: 시트 사용법 | B11: 표준용어 시트의 '데이터타입' 열은 표준도메인 시트에서 자동으로 조회된다. 도메인의 타입을 바꾸면 해당 도메인을 쓰는 모든 용어의 타입이 함께 바뀐다.
A12: 색상 | B12: 노란색 행은 분류어(도메인을 결정하는 단어)이다.
A13: 관련 문서 | B13: decision_log.md (설계 의사결정), 변경이력 시트 (표준화 과정에서 바뀐 속성명)

Sheet 표준단어
A1: No | B1: 표준단어 | C1: 영문약어 | D1: 영문명 | E1: 분류어여부 | F1: 금칙어·이음동의어 | G1: 설명
A2: 1 | B2: ID | C2: ID | D2: Identifier | E2: Y | G2: 대체키 식별자
A3: 2 | B3: 번호 | C3: NO | D3: Number | E3: Y | G3: 원천 식별자, 우편번호 등 문자형 번호
A4: 3 | B4: 코드 | C4: CD | D4: Code | E4: Y | G4: 표준코드 시트에 값이 정의된 속성
A5: 4 | B5: 명 | C5: NM | D5: Name | E5: Y | F5: 이름 | G5: 명칭
A6: 5 | B6: 일시 | C6: DTM | D6: Datetime | E6: Y | F6: 시각, 시간 | G6: 날짜와 시각
A7: 6 | B7: 일자 | C7: DT | D7: Date | E7: Y | F7: 날짜 | G7: 날짜만
A8: 7 | B8: 금액 | C8: AMT | D8: Amount | E8: Y | F8: 액 | G8: 화폐 금액
A9: 8 | B9: 정가 | C9: LPRC | D9: List Price | E9: Y | F9: 소비자가 | G9: 상품의 정상 판매가격
A10: 9 | B10: 단가 | C10: UPRC | D10: Unit Price | E10: Y | G10: 1개당 가격
A11: 10 | B11: 비 | C11: FEE | D11: Fee | E11: Y | F11: 비용, 료 | G11: 수수료·운임 성격의 금액
A12: 11 | B12: 수량 | C12: QTY | D12: Quantity | E12: Y | F12: 개수 | G12: 상품 개수
A13: 12 | B13: 순번 | C13: SEQ | D13: Sequence | E13: Y | F13: 일련번호 | G13: 상위 키 안에서의 순서
A14: 13 | B14: 수 | C14: CNT | D14: Count | E14: Y | G14: 횟수·개월 등 개수
A15: 14 | B15: 레벨 | C15: LVL | D15: Level | E15: Y | F15: 단계, 깊이 | G15: 계층 단계
A16: 15 | B16: 중량 | C16: WT | D16: Weight | E16: Y | F16: 무게 | G16: 그램(g) 단위
A17: 16 | B17: 길이 | C17: LEN | D17: Length | E17: Y | G17: 센티미터(cm) 단위
A18: 17 | B18: 높이 | C18: HGT | D18: Height | E18: Y | G18: 센티미터(cm) 단위
A19: 18 | B19: 너비 | C19: WDT | D19: Width | E19: Y | F19: 폭 | G19: 센티미터(cm) 단위
A20: 19 | B20: 회원 | C20: MBR | D20: Member | E20: N
A21: 20 | B21: 원천 | C21: SRC | D21: Source | E21: N | G21: 원천 시스템(온라인몰) 값
A22: 21 | B22: 가입 | C22: JOIN | D22: Join | E22: N
A23: 22 | B23: 채널 | C23: CHNL | D23: Channel | E23: N
A24: 23 | B24: 우편 | C24: ZIP | D24: Zip | E24: N | G24: 우편번호 구성 단어
A25: 24 | B25: 도시 | C25: CITY | D25: City | E25: N
A26: 25 | B26: 주 | C26: ST | D26: State | E26: N | G26: 행정구역(주)
A27: 26 | B27: 브랜드 | C27: BRND | D27: Brand | E27: N
A28: 27 | B28: 카테고리 | C28: CTGR | D28: Category | E28: N | F28: 분류
A29: 28 | B29: 상위 | C29: UPPR | D29: Upper | E29: N | F29: 부모
A30: 29 | B30: 상품 | C30: PRD | D30: Product | E30: N | F30: 제품
A31: 30 | B31: 옵션 | C31: OPT | D31: Option | E31: N
A32: 31 | B32: 매장 | C32: STR | D32: Store | E32: N | F32: 점포, 스토어
A33: 32 | B33: 개점 | C33: OPEN | D33: Open | E33: N | F33: 오픈
A34: 33 | B34: 재고 | C34: STCK | D34: Stock | E34: N
A35: 34 | B35: 상태 | C35: STAT | D35: Status | E35: N
A36: 35 | B36: 최종 | C36: LAST | D36: Last | E36: N | F36: 마지막
A37: 36 | B37: 변동 | C37: CHG | D37: Change | E37: N | F37: 변경 | G37: 재고·상태의 변화
A38: 37 | B38: 유형 | C38: TYPE | D38: Type | E38: N | F38: 종류
A39: 38 | B39: 조정 | C39: ADJ | D39: Adjustment | E39: N
A40: 39 | B40: 사유 | C40: RSN | D40: Reason | E40: N | F40: 원인
...

Sheet 표준도메인
A1: No | B1: 도메인명 | C1: 분류어 | D1: 데이터타입 | E1: 길이 | F1: 소수점 | G1: 타입표현 | H1: 설명
A2: 1 | B2: ID_N | C2: ID | D2: BIGINT | G2: =IF(E2="",D2,IF(F2="",D2&"("&E2&")",D2&"("&E2&","&F2&")")) -> BIGINT | H2: 대체키 일련번호
A3: 2 | B3: NO_V32 | C3: 번호 | D3: VARCHAR | E3: 32 | G3: =IF(E3="",D3,IF(F3="",D3&"("&E3&")",D3&"("&E3&","&F3&")")) -> VARCHAR(32) | H3: 원천 시스템 식별자 (32자리 해시값)
A4: 3 | B4: NO_V10 | C4: 번호 | D4: VARCHAR | E4: 10 | G4: =IF(E4="",D4,IF(F4="",D4&"("&E4&")",D4&"("&E4&","&F4&")")) -> VARCHAR(10) | H4: 우편번호. 앞자리 0 보존을 위해 문자형
A5: 4 | B5: CD_V20 | C5: 코드 | D5: VARCHAR | E5: 20 | G5: =IF(E5="",D5,IF(F5="",D5&"("&E5&")",D5&"("&E5&","&F5&")")) -> VARCHAR(20) | H5: 표준코드 값
A6: 5 | B6: NM_V100 | C6: 명 | D6: VARCHAR | E6: 100 | G6: =IF(E6="",D6,IF(F6="",D6&"("&E6&")",D6&"("&E6&","&F6&")")) -> VARCHAR(100) | H6: 명칭
A7: 6 | B7: DTM | C7: 일시 | D7: DATETIME | G7: =IF(E7="",D7,IF(F7="",D7&"("&E7&")",D7&"("&E7&","&F7&")")) -> DATETIME | H7: 날짜와 시각. MySQL TIMESTAMP는 2038년 제한·시간대 변환이 있어 DATETIME 사용
A8: 7 | B8: DT | C8: 일자 | D8: DATE | G8: =IF(E8="",D8,IF(F8="",D8&"("&E8&")",D8&"("&E8&","&F8&")")) -> DATE | H8: 날짜
A9: 8 | B9: AMT_N12_2 | C9: 금액, 정가, 단가, 비 | D9: DECIMAL | E9: 12 | F9: 2 | G9: =IF(E9="",D9,IF(F9="",D9&"("&E9&")",D9&"("&E9&","&F9&")")) -> DECIMAL(12,2) | H9: 화폐 금액 (통화 BRL, D-016)
A10: 9 | B10: QTY_N | C10: 수량 | D10: INTEGER | G10: =IF(E10="",D10,IF(F10="",D10&"("&E10&")",D10&"("&E10&","&F10&")")) -> INTEGER | H10: 변동수량은 음수 허용
A11: 10 | B11: SEQ_N | C11: 순번 | D11: INTEGER | G11: =IF(E11="",D11,IF(F11="",D11&"("&E11&")",D11&"("&E11&","&F11&")")) -> INTEGER | H11: 1부터 시작
A12: 11 | B12: CNT_N | C12: 수 | D12: INTEGER | G12: =IF(E12="",D12,IF(F12="",D12&"("&E12&")",D12&"("&E12&","&F12&")")) -> INTEGER | H12: 0 이상
A13: 12 | B13: LVL_N | C13: 레벨 | D13: SMALLINT | G13: =IF(E13="",D13,IF(F13="",D13&"("&E13&")",D13&"("&E13&","&F13&")")) -> SMALLINT | H13: 1 대분류 / 2 중분류
A14: 13 | B14: WT_N | C14: 중량 | D14: INTEGER | G14: =IF(E14="",D14,IF(F14="",D14&"("&E14&")",D14&"("&E14&","&F14&")")) -> INTEGER | H14: 단위 g
A15: 14 | B15: LEN_N | C15: 길이, 높이, 너비 | D15: INTEGER | G15: =IF(E15="",D15,IF(F15="",D15&"("&E15&")",D15&"("&E15&","&F15&")")) -> INTEGER | H15: 단위 cm

Sheet 표준용어
A1: No | B1: 표준용어 | C1: 물리명 | D1: 구성단어 | E1: 도메인명 | F1: 데이터타입 | G1: 사용테이블 | H1: 설명
A2: 1 | B2: 회원ID | C2: MBR_ID | D2: 회원+ID | E2: ID_N | F2: =IFERROR(INDEX(표준도메인!$G:$G,MATCH(E2,표준도메인!$B:$B,0)),"도메인 없음") -> BIGINT | G2: 회원, 주문
A3: 2 | B3: 원천회원번호 | C3: SRC_MBR_NO | D3: 원천+회원+번호 | E3: NO_V32 | F3: =IFERROR(INDEX(표준도메인!$G:$G,MATCH(E3,표준도메인!$B:$B,0)),"도메인 없음") -> VARCHAR(32) | G3: 회원 | H3: customer_unique_id (D-011)
A4: 3 | B4: 가입채널코드 | C4: JOIN_CHNL_CD | D4: 가입+채널+코드 | E4: CD_V20 | F4: =IFERROR(INDEX(표준도메인!$G:$G,MATCH(E4,표준도메인!$B:$B,0)),"도메인 없음") -> VARCHAR(20) | G4: 회원
A5: 4 | B5: 가입일시 | C5: JOIN_DTM | D5: 가입+일시 | E5: DTM | F5: =IFERROR(INDEX(표준도메인!$G:$G,MATCH(E5,표준도메인!$B:$B,0)),"도메인 없음") -> DATETIME | G5: 회원 | H5: Olist는 첫 주문일시 (D-023)
A6: 5 | B6: 우편번호 | C6: ZIP_NO | D6: 우편+번호 | E6: NO_V10 | F6: =IFERROR(INDEX(표준도메인!$G:$G,MATCH(E6,표준도메인!$B:$B,0)),"도메인 없음") -> VARCHAR(10) | G6: 회원, 매장
A7: 6 | B7: 도시명 | C7: CITY_NM | D7: 도시+명 | E7: NM_V100 | F7: =IFERROR(INDEX(표준도메인!$G:$G,MATCH(E7,표준도메인!$B:$B,0)),"도메인 없음") -> VARCHAR(100) | G7: 회원, 매장
A8: 7 | B8: 주명 | C8: ST_NM | D8: 주+명 | E8: NM_V100 | F8: =IFERROR(INDEX(표준도메인!$G:$G,MATCH(E8,표준도메인!$B:$B,0)),"도메인 없음") -> VARCHAR(100) | G8: 회원, 매장
A9: 8 | B9: 브랜드ID | C9: BRND_ID | D9: 브랜드+ID | E9: ID_N | F9: =IFERROR(INDEX(표준도메인!$G:$G,MATCH(E9,표준도메인!$B:$B,0)),"도메인 없음") -> BIGINT | G9: 브랜드, 상품
A10: 9 | B10: 브랜드명 | C10: BRND_NM | D10: 브랜드+명 | E10: NM_V100 | F10: =IFERROR(INDEX(표준도메인!$G:$G,MATCH(E10,표준도메인!$B:$B,0)),"도메인 없음") -> VARCHAR(100) | G10: 브랜드
A11: 10 | B11: 카테고리ID | C11: CTGR_ID | D11: 카테고리+ID | E11: ID_N | F11: =IFERROR(INDEX(표준도메인!$G:$G,MATCH(E11,표준도메인!$B:$B,0)),"도메인 없음") -> BIGINT | G11: 카테고리, 상품
A12: 11 | B12: 상위카테고리ID | C12: UPPR_CTGR_ID | D12: 상위+카테고리+ID | E12: ID_N | F12: =IFERROR(INDEX(표준도메인!$G:$G,MATCH(E12,표준도메인!$B:$B,0)),"도메인 없음") -> BIGINT | G12: 카테고리 | H12: 자기참조, NULL 허용
A13: 12 | B13: 카테고리명 | C13: CTGR_NM | D13: 카테고리+명 | E13: NM_V100 | F13: =IFERROR(INDEX(표준도메인!$G:$G,MATCH(E13,표준도메인!$B:$B,0)),"도메인 없음") -> VARCHAR(100) | G13: 카테고리
A14: 13 | B14: 카테고리레벨 | C14: CTGR_LVL | D14: 카테고리+레벨 | E14: LVL_N | F14: =IFERROR(INDEX(표준도메인!$G:$G,MATCH(E14,표준도메인!$B:$B,0)),"도메인 없음") -> SMALLINT | G14: 카테고리
A15: 14 | B15: 원천카테고리코드 | C15: SRC_CTGR_CD | D15: 원천+카테고리+코드 | E15: CD_V20 | F15: =IFERROR(INDEX(표준도메인!$G:$G,MATCH(E15,표준도메인!$B:$B,0)),"도메인 없음") -> VARCHAR(20) | G15: 카테고리 | H15: beleza_saude
A16: 15 | B16: 상품ID | C16: PRD_ID | D16: 상품+ID | E16: ID_N | F16: =IFERROR(INDEX(표준도메인!$G:$G,MATCH(E16,표준도메인!$B:$B,0)),"도메인 없음") -> BIGINT | G16: 상품, 상품옵션
A17: 16 | B17: 원천상품번호 | C17: SRC_PRD_NO | D17: 원천+상품+번호 | E17: NO_V32 | F17: =IFERROR(INDEX(표준도메인!$G:$G,MATCH(E17,표준도메인!$B:$B,0)),"도메인 없음") -> VARCHAR(32) | G17: 상품 | H17: product_id
A18: 17 | B18: 상품명 | C18: PRD_NM | D18: 상품+명 | E18: NM_V100 | F18: =IFERROR(INDEX(표준도메인!$G:$G,MATCH(E18,표준도메인!$B:$B,0)),"도메인 없음") -> VARCHAR(100) | G18: 상품 | H18: 가상 생성 (D-015)
A19: 18 | B19: 정가 | C19: LPRC | D19: 정가 | E19: AMT_N12_2 | F19: =IFERROR(INDEX(표준도메인!$G:$G,MATCH(E19,표준도메인!$B:$B,0)),"도메인 없음") -> DECIMAL(12,2) | G19: 상품 | H19: 원천 판매가 최댓값 (D-015)
A20: 19 | B20: 중량 | C20: WT | D20: 중량 | E20: WT_N | F20: =IFERROR(INDEX(표준도메인!$G:$G,MATCH(E20,표준도메인!$B:$B,0)),"도메인 없음") -> INTEGER | G20: 상품 | H20: product_weight_g
A21: 20 | B21: 길이 | C21: LEN | D21: 길이 | E21: LEN_N | F21: =IFERROR(INDEX(표준도메인!$G:$G,MATCH(E21,표준도메인!$B:$B,0)),"도메인 없음") -> INTEGER | G21: 상품 | H21: product_length_cm
A22: 21 | B22: 높이 | C22: HGT | D22: 높이 | E22: LEN_N | F22: =IFERROR(INDEX(표준도메인!$G:$G,MATCH(E22,표준도메인!$B:$B,0)),"도메인 없음") -> INTEGER | G22: 상품 | H22: product_height_cm
A23: 22 | B23: 너비 | C23: WDT | D23: 너비 | E23: LEN_N | F23: =IFERROR(INDEX(표준도메인!$G:$G,MATCH(E23,표준도메인!$B:$B,0)),"도메인 없음") -> INTEGER | G23: 상품 | H23: product_width_cm
A24: 23 | B24: 상품옵션ID | C24: PRD_OPT_ID | D24: 상품+옵션+ID | E24: ID_N | F24: =IFERROR(INDEX(표준도메인!$G:$G,MATCH(E24,표준도메인!$B:$B,0)),"도메인 없음") -> BIGINT | G24: 상품옵션, 매장재고, 재고변동이력, 주문상세
A25: 24 | B25: 옵션명 | C25: OPT_NM | D25: 옵션+명 | E25: NM_V100 | F25: =IFERROR(INDEX(표준도메인!$G:$G,MATCH(E25,표준도메인!$B:$B,0)),"도메인 없음") -> VARCHAR(100) | G25: 상품옵션
A26: 25 | B26: 매장ID | C26: STR_ID | D26: 매장+ID | E26: ID_N | F26: =IFERROR(INDEX(표준도메인!$G:$G,MATCH(E26,표준도메인!$B:$B,0)),"도메인 없음") -> BIGINT | G26: 매장, 매장재고, 재고변동이력, 주문
A27: 26 | B27: 매장명 | C27: STR_NM | D27: 매장+명 | E27: NM_V100 | F27: =IFERROR(INDEX(표준도메인!$G:$G,MATCH(E27,표준도메인!$B:$B,0)),"도메인 없음") -> VARCHAR(100) | G27: 매장
A28: 27 | B28: 개점일자 | C28: OPEN_DT | D28: 개점+일자 | E28: DT | F28: =IFERROR(INDEX(표준도메인!$G:$G,MATCH(E28,표준도메인!$B:$B,0)),"도메인 없음") -> DATE | G28: 매장
A29: 28 | B29: 재고상태코드 | C29: STCK_STAT_CD | D29: 재고+상태+코드 | E29: CD_V20 | F29: =IFERROR(INDEX(표준도메인!$G:$G,MATCH(E29,표준도메인!$B:$B,0)),"도메인 없음") -> VARCHAR(20) | G29: 매장재고, 재고변동이력 | H29: D-002
A30: 29 | B30: 재고수량 | C30: STCK_QTY | D30: 재고+수량 | E30: QTY_N | F30: =IFERROR(INDEX(표준도메인!$G:$G,MATCH(E30,표준도메인!$B:$B,0)),"도메인 없음") -> INTEGER | G30: 매장재고
A31: 30 | B31: 최종변동일시 | C31: LAST_CHG_DTM | D31: 최종+변동+일시 | E31: DTM | F31: =IFERROR(INDEX(표준도메인!$G:$G,MATCH(E31,표준도메인!$B:$B,0)),"도메인 없음") -> DATETIME | G31: 매장재고 | H31: 변경이력 1
A32: 31 | B32: 재고변동ID | C32: STCK_CHG_ID | D32: 재고+변동+ID | E32: ID_N | F32: =IFERROR(INDEX(표준도메인!$G:$G,MATCH(E32,표준도메인!$B:$B,0)),"도메인 없음") -> BIGINT | G32: 재고변동이력
A33: 32 | B33: 변동유형코드 | C33: CHG_TYPE_CD | D33: 변동+유형+코드 | E33: CD_V20 | F33: =IFERROR(INDEX(표준도메인!$G:$G,MATCH(E33,표준도메인!$B:$B,0)),"도메인 없음") -> VARCHAR(20) | G33: 재고변동이력
A34: 33 | B34: 변동수량 | C34: CHG_QTY | D34: 변동+수량 | E34: QTY_N | F34: =IFERROR(INDEX(표준도메인!$G:$G,MATCH(E34,표준도메인!$B:$B,0)),"도메인 없음") -> INTEGER | G34: 재고변동이력 | H34: 증가 +, 감소 −
A35: 34 | B35: 변동일시 | C35: CHG_DTM | D35: 변동+일시 | E35: DTM | F35: =IFERROR(INDEX(표준도메인!$G:$G,MATCH(E35,표준도메인!$B:$B,0)),"도메인 없음") -> DATETIME | G35: 재고변동이력
A36: 35 | B36: 조정사유코드 | C36: ADJ_RSN_CD | D36: 조정+사유+코드 | E36: CD_V20 | F36: =IFERROR(INDEX(표준도메인!$G:$G,MATCH(E36,표준도메인!$B:$B,0)),"도메인 없음") -> VARCHAR(20) | G36: 재고변동이력 | H36: D-007
A37: 36 | B37: 주문ID | C37: ORD_ID | D37: 주문+ID | E37: ID_N | F37: =IFERROR(INDEX(표준도메인!$G:$G,MATCH(E37,표준도메인!$B:$B,0)),"도메인 없음") -> BIGINT | G37: 주문, 주문상세, 결제, 재고변동이력
A38: 37 | B38: 원천주문번호 | C38: SRC_ORD_NO | D38: 원천+주문+번호 | E38: NO_V32 | F38: =IFERROR(INDEX(표준도메인!$G:$G,MATCH(E38,표준도메인!$B:$B,0)),"도메인 없음") -> VARCHAR(32) | G38: 주문 | H38: order_id
A39: 38 | B39: 판매채널코드 | C39: SALE_CHNL_CD | D39: 판매+채널+코드 | E39: CD_V20 | F39: =IFERROR(INDEX(표준도메인!$G:$G,MATCH(E39,표준도메인!$B:$B,0)),"도메인 없음") -> VARCHAR(20) | G39: 주문 | H39: D-017
A40: 39 | B40: 주문상태코드 | C40: ORD_STAT_CD | D40: 주문+상태+코드 | E40: CD_V20 | F40: =IFERROR(INDEX(표준도메인!$G:$G,MATCH(E40,표준도메인!$B:$B,0)),"도메인 없음") -> VARCHAR(20) | G40: 주문
...

Sheet 표준코드
A1: No | B1: 코드그룹 | C1: 코드값 | D1: 코드명 | E1: 원천값(Olist) | F1: 설명
A2: 1 | B2: 판매채널코드 | C2: STORE | D2: 매장판매 | F2: 회원ID NULL 허용
A3: 2 | B3: 판매채널코드 | C3: PARCEL | D3: 택배배송 | E3: Olist 전체 주문 | F3: 출고매장 없음
A4: 3 | B4: 판매채널코드 | C4: STORE_SHIP | D4: 매장출고배송 | F4: 매장에서 포장 후 배송
A5: 4 | B5: 판매채널코드 | C5: PICKUP | D5: 매장픽업 | F5: 매장에서 포장 후 고객 수령
A6: 5 | B6: 주문상태코드 | C6: ORDERED | D6: 주문접수 | E6: created
A7: 6 | B7: 주문상태코드 | C7: PAID | D7: 결제완료 | E7: approved, invoiced, processing | F7: 출고 준비 단계 포함
A8: 7 | B8: 주문상태코드 | C8: PACKED | D8: 포장완료 | F8: 매장출고배송·매장픽업
A9: 8 | B9: 주문상태코드 | C9: SHIPPED | D9: 배송중 | E9: shipped
A10: 9 | B10: 주문상태코드 | C10: RECEIVED | D10: 수령완료 | E10: delivered | F10: D-022
A11: 10 | B11: 주문상태코드 | C11: CANCELED | D11: 취소 | E11: canceled, unavailable
A12: 11 | B12: 재고상태코드 | C12: AVAIL | D12: 가용 | F12: 판매 가능 (D-002)
A13: 12 | B13: 재고상태코드 | C13: ORD_HOLD | D13: 주문보관 | F13: 포장된 주문 봉투 안
A14: 13 | B14: 재고상태코드 | C14: TESTER | D14: 테스터 | F14: D-003
A15: 14 | B15: 변동유형코드 | C15: IN | D15: 입고 | F15: 가용 +
A16: 15 | B16: 변동유형코드 | C16: SALE | D16: 판매 | F16: 가용 −, 매장판매
A17: 16 | B17: 변동유형코드 | C17: ORD_ALLOC | D17: 주문할당 | F17: 가용 −, 주문보관 +
A18: 17 | B18: 변동유형코드 | C18: ORD_RCV | D18: 주문수령 | F18: 주문보관 −, 픽업 수령·매장출고
A19: 18 | B19: 변동유형코드 | C19: ORD_CNCL | D19: 주문취소복원 | F19: 주문보관 −, 가용 + (D-006)
A20: 19 | B20: 변동유형코드 | C20: RETURN | D20: 반품 | F20: 가용 +
A21: 20 | B21: 변동유형코드 | C21: DISPOSE | D21: 폐기 | F21: 가용 −
A22: 21 | B22: 변동유형코드 | C22: ADJ | D22: 실사조정 | F22: 가용 ±, 조정사유코드 필수
A23: 22 | B23: 변동유형코드 | C23: TESTER_IN | D23: 테스터전환 | F23: 가용 −, 테스터 +
A24: 23 | B24: 변동유형코드 | C24: TESTER_OUT | D24: 테스터폐기 | F24: 테스터 −
A25: 24 | B25: 조정사유코드 | C25: THEFT | D25: 도난추정
A26: 25 | B26: 조정사유코드 | C26: DAMAGE | D26: 파손
A27: 26 | B27: 조정사유코드 | C27: POS_ERR | D27: 포스오류
A28: 27 | B28: 조정사유코드 | C28: UNKNOWN | D28: 원인미상 | F28: D-007
A29: 28 | B29: 조정사유코드 | C29: FOUND | D29: 미발견후발견 | F29: 재조정 사유 (D-007)
A30: 29 | B30: 결제수단코드 | C30: CREDIT | D30: 신용카드 | E30: credit_card
A31: 30 | B31: 결제수단코드 | C31: DEBIT | D31: 체크카드 | E31: debit_card
A32: 31 | B32: 결제수단코드 | C32: BANK_SLIP | D32: 은행전표 | E32: boleto | F32: 원천 국가의 전표 결제
A33: 32 | B33: 결제수단코드 | C33: VOUCHER | D33: 상품권 | E33: voucher
A34: 33 | B34: 결제수단코드 | C34: CASH | D34: 현금 | F34: 매장판매 전용
A35: 34 | B35: 가입채널코드 | C35: ONLINE | D35: 온라인 | E35: Olist 전체 회원
A36: 35 | B36: 가입채널코드 | C36: STORE | D36: 매장

Sheet 변경이력
A1: No | B1: 변경 전 (논리 ERD) | C1: 변경 후 (표준용어) | D1: 사유
A2: 1 | B2: 최종변경일시 | C2: 최종변동일시 | D2: '변경'과 '변동'이 같은 의미로 혼용됨. '변경'(행 갱신)과 '변동'(재고 증감)으로 구분하는 안도 검토했으나, 매장재고의 최종 갱신은 곧 마지막 재고 변동이므로 '변동'으로 통일하고 '변경'은 금칙어로 등록
A3: 2 | B3: 인도완료일시 | C3: 수령완료일시 | D3: '인도'는 현업에서 잘 쓰지 않아 부자연스러움. '도착'도 검토했으나 매장 픽업·매장판매에는 맞지 않아, 모든 채널에 자연스러운 '수령'으로 결정
A4: 3 | B4: 예상배송일자 | C4: 예상수령일자 | D4: 실제 값인 수령완료일시와 비교 대상임이 이름에서 드러나도록 같은 단어 '수령'으로 통일. '배송' 유지안, '인도'안, '도착'안을 검토
